[2025-02-03T07:50:28.438+0000] {local_task_job_runner.py:123} INFO - ::group::Pre task execution logs
[2025-02-03T07:50:28.451+0000] {taskinstance.py:2613} INFO - Dependencies all met for dep_context=non-requeueable deps ti=<TaskInstance: test_workflow.get_brand_mappings manual__2025-02-03T07:50:24.983948+00:00 [queued]>
[2025-02-03T07:50:28.459+0000] {taskinstance.py:2613} INFO - Dependencies all met for dep_context=requeueable deps ti=<TaskInstance: test_workflow.get_brand_mappings manual__2025-02-03T07:50:24.983948+00:00 [queued]>
[2025-02-03T07:50:28.459+0000] {taskinstance.py:2866} INFO - Starting attempt 1 of 1
[2025-02-03T07:50:28.469+0000] {taskinstance.py:2889} INFO - Executing <Task(DockerOperator): get_brand_mappings> on 2025-02-03 07:50:24.983948+00:00
[2025-02-03T07:50:28.476+0000] {warnings.py:112} WARNING - /home/***/.local/lib/python3.12/site-packages/***/task/task_runner/standard_task_runner.py:70: DeprecationWarning: This process (pid=244) is multi-threaded, use of fork() may lead to deadlocks in the child.
  pid = os.fork()

[2025-02-03T07:50:28.477+0000] {standard_task_runner.py:72} INFO - Started process 249 to run task
[2025-02-03T07:50:28.478+0000] {standard_task_runner.py:104} INFO - Running: ['***', 'tasks', 'run', 'test_workflow', 'get_brand_mappings', 'manual__2025-02-03T07:50:24.983948+00:00', '--job-id', '4', '--raw', '--subdir', 'DAGS_FOLDER/test_dag.py', '--cfg-path', '/tmp/tmppnwpqvi1']
[2025-02-03T07:50:28.479+0000] {standard_task_runner.py:105} INFO - Job 4: Subtask get_brand_mappings
[2025-02-03T07:50:28.525+0000] {task_command.py:467} INFO - Running <TaskInstance: test_workflow.get_brand_mappings manual__2025-02-03T07:50:24.983948+00:00 [running]> on host d2ed8e5dfce8
[2025-02-03T07:50:28.637+0000] {taskinstance.py:3132} INFO - Exporting env vars: AIRFLOW_CTX_DAG_OWNER='***' AIRFLOW_CTX_DAG_ID='test_workflow' AIRFLOW_CTX_TASK_ID='get_brand_mappings' AIRFLOW_CTX_EXECUTION_DATE='2025-02-03T07:50:24.983948+00:00' AIRFLOW_CTX_TRY_NUMBER='1' AIRFLOW_CTX_DAG_RUN_ID='manual__2025-02-03T07:50:24.983948+00:00'
[2025-02-03T07:50:28.639+0000] {logging_mixin.py:190} INFO - Task instance is in running state
[2025-02-03T07:50:28.639+0000] {logging_mixin.py:190} INFO -  Previous state of the Task instance: queued
[2025-02-03T07:50:28.640+0000] {logging_mixin.py:190} INFO - Current task name:get_brand_mappings state:running start_date:2025-02-03 07:50:28.451861+00:00
[2025-02-03T07:50:28.640+0000] {logging_mixin.py:190} INFO - Dag name:test_workflow and current dag run status:running
[2025-02-03T07:50:28.641+0000] {taskinstance.py:731} INFO - ::endgroup::
[2025-02-03T07:50:28.647+0000] {docker.py:157} ERROR - Failed to establish connection to Docker host unix://var/run/docker.sock: Error while fetching server API version: ('Connection aborted.', FileNotFoundError(2, 'No such file or directory'))
[2025-02-03T07:50:28.657+0000] {taskinstance.py:3311} ERROR - Task failed with exception
Traceback (most recent call last):
  File "/home/airflow/.local/lib/python3.12/site-packages/airflow/models/taskinstance.py", line 767, in _execute_task
    result = _execute_callable(context=context, **execute_callable_kwargs)
             ^^^^^^^^^^^^^^^^^^^^^^^^^^^^^^^^^^^^^^^^^^^^^^^^^^^^^^^^^^^^^
  File "/home/airflow/.local/lib/python3.12/site-packages/airflow/models/taskinstance.py", line 733, in _execute_callable
    return ExecutionCallableRunner(
           ^^^^^^^^^^^^^^^^^^^^^^^^
  File "/home/airflow/.local/lib/python3.12/site-packages/airflow/utils/operator_helpers.py", line 252, in run
    return self.func(*args, **kwargs)
           ^^^^^^^^^^^^^^^^^^^^^^^^^^
  File "/home/airflow/.local/lib/python3.12/site-packages/airflow/models/baseoperator.py", line 422, in wrapper
    return func(self, *args, **kwargs)
           ^^^^^^^^^^^^^^^^^^^^^^^^^^^
  File "/home/airflow/.local/lib/python3.12/site-packages/airflow/providers/docker/operators/docker.py", line 501, in execute
    if self.force_pull or not self.cli.images(name=self.image):
                              ^^^^^^^^
  File "/home/airflow/.local/lib/python3.12/site-packages/airflow/providers/docker/operators/docker.py", line 375, in cli
    return self.hook.api_client
           ^^^^^^^^^^^^^^^^^^^^
  File "/usr/local/lib/python3.12/functools.py", line 995, in __get__
    val = self.func(instance)
          ^^^^^^^^^^^^^^^^^^^
  File "/home/airflow/.local/lib/python3.12/site-packages/airflow/providers/docker/hooks/docker.py", line 161, in api_client
    raise AirflowException("Failed to establish connection to any given Docker hosts.")
airflow.exceptions.AirflowException: Failed to establish connection to any given Docker hosts.
[2025-02-03T07:50:28.662+0000] {logging_mixin.py:190} INFO - Task instance in failure state
[2025-02-03T07:50:28.662+0000] {logging_mixin.py:190} INFO - Task start:2025-02-03 07:50:28.451861+00:00 end:2025-02-03 07:50:28.662190+00:00 duration:0.210329
[2025-02-03T07:50:28.663+0000] {logging_mixin.py:190} INFO - Task:<Task(DockerOperator): get_brand_mappings> dag:<DAG: test_workflow> dagrun:<DagRun test_workflow @ 2025-02-03 07:50:24.983948+00:00: manual__2025-02-03T07:50:24.983948+00:00, state:running, queued_at: 2025-02-03 07:50:25.004643+00:00. externally triggered: True>
[2025-02-03T07:50:28.663+0000] {logging_mixin.py:190} INFO - Failure caused by Failed to establish connection to any given Docker hosts.
[2025-02-03T07:50:28.663+0000] {taskinstance.py:1225} INFO - Marking task as FAILED. dag_id=test_workflow, task_id=get_brand_mappings, run_id=manual__2025-02-03T07:50:24.983948+00:00, execution_date=20250203T075024, start_date=20250203T075028, end_date=20250203T075028
[2025-02-03T07:50:28.679+0000] {taskinstance.py:340} INFO - ::group::Post task execution logs
[2025-02-03T07:50:28.679+0000] {standard_task_runner.py:124} ERROR - Failed to execute job 4 for task get_brand_mappings (Failed to establish connection to any given Docker hosts.; 249)
Traceback (most recent call last):
  File "/home/airflow/.local/lib/python3.12/site-packages/airflow/task/task_runner/standard_task_runner.py", line 117, in _start_by_fork
    ret = args.func(args, dag=self.dag)
          ^^^^^^^^^^^^^^^^^^^^^^^^^^^^^
  File "/home/airflow/.local/lib/python3.12/site-packages/airflow/cli/cli_config.py", line 49, in command
    return func(*args, **kwargs)
           ^^^^^^^^^^^^^^^^^^^^^
  File "/home/airflow/.local/lib/python3.12/site-packages/airflow/utils/cli.py", line 116, in wrapper
    return f(*args, **kwargs)
           ^^^^^^^^^^^^^^^^^^
  File "/home/airflow/.local/lib/python3.12/site-packages/airflow/cli/commands/task_command.py", line 483, in task_run
    task_return_code = _run_task_by_selected_method(args, _dag, ti)
                       ^^^^^^^^^^^^^^^^^^^^^^^^^^^^^^^^^^^^^^^^^^^^
  File "/home/airflow/.local/lib/python3.12/site-packages/airflow/cli/commands/task_command.py", line 256, in _run_task_by_selected_method
    return _run_raw_task(args, ti)
           ^^^^^^^^^^^^^^^^^^^^^^^
  File "/home/airflow/.local/lib/python3.12/site-packages/airflow/cli/commands/task_command.py", line 341, in _run_raw_task
    return ti._run_raw_task(
           ^^^^^^^^^^^^^^^^^
  File "/home/airflow/.local/lib/python3.12/site-packages/airflow/utils/session.py", line 97, in wrapper
    return func(*args, session=session, **kwargs)
           ^^^^^^^^^^^^^^^^^^^^^^^^^^^^^^^^^^^^^^
  File "/home/airflow/.local/lib/python3.12/site-packages/airflow/models/taskinstance.py", line 3005, in _run_raw_task
    return _run_raw_task(
           ^^^^^^^^^^^^^^
  File "/home/airflow/.local/lib/python3.12/site-packages/airflow/models/taskinstance.py", line 273, in _run_raw_task
    TaskInstance._execute_task_with_callbacks(
  File "/home/airflow/.local/lib/python3.12/site-packages/airflow/models/taskinstance.py", line 3159, in _execute_task_with_callbacks
    result = self._execute_task(context, task_orig)
             ^^^^^^^^^^^^^^^^^^^^^^^^^^^^^^^^^^^^^^
  File "/home/airflow/.local/lib/python3.12/site-packages/airflow/models/taskinstance.py", line 3183, in _execute_task
    return _execute_task(self, context, task_orig)
           ^^^^^^^^^^^^^^^^^^^^^^^^^^^^^^^^^^^^^^^
  File "/home/airflow/.local/lib/python3.12/site-packages/airflow/models/taskinstance.py", line 767, in _execute_task
    result = _execute_callable(context=context, **execute_callable_kwargs)
             ^^^^^^^^^^^^^^^^^^^^^^^^^^^^^^^^^^^^^^^^^^^^^^^^^^^^^^^^^^^^^
  File "/home/airflow/.local/lib/python3.12/site-packages/airflow/models/taskinstance.py", line 733, in _execute_callable
    return ExecutionCallableRunner(
           ^^^^^^^^^^^^^^^^^^^^^^^^
  File "/home/airflow/.local/lib/python3.12/site-packages/airflow/utils/operator_helpers.py", line 252, in run
    return self.func(*args, **kwargs)
           ^^^^^^^^^^^^^^^^^^^^^^^^^^
  File "/home/airflow/.local/lib/python3.12/site-packages/airflow/models/baseoperator.py", line 422, in wrapper
    return func(self, *args, **kwargs)
           ^^^^^^^^^^^^^^^^^^^^^^^^^^^
  File "/home/airflow/.local/lib/python3.12/site-packages/airflow/providers/docker/operators/docker.py", line 501, in execute
    if self.force_pull or not self.cli.images(name=self.image):
                              ^^^^^^^^
  File "/home/airflow/.local/lib/python3.12/site-packages/airflow/providers/docker/operators/docker.py", line 375, in cli
    return self.hook.api_client
           ^^^^^^^^^^^^^^^^^^^^
  File "/usr/local/lib/python3.12/functools.py", line 995, in __get__
    val = self.func(instance)
          ^^^^^^^^^^^^^^^^^^^
  File "/home/airflow/.local/lib/python3.12/site-packages/airflow/providers/docker/hooks/docker.py", line 161, in api_client
    raise AirflowException("Failed to establish connection to any given Docker hosts.")
airflow.exceptions.AirflowException: Failed to establish connection to any given Docker hosts.
[2025-02-03T07:50:28.691+0000] {local_task_job_runner.py:266} INFO - Task exited with return code 1
[2025-02-03T07:50:28.713+0000] {taskinstance.py:3895} INFO - 0 downstream tasks scheduled from follow-on schedule check
[2025-02-03T07:50:28.714+0000] {local_task_job_runner.py:245} INFO - ::endgroup::
