[2025-02-04T01:35:26.900+0000] {local_task_job_runner.py:123} INFO - ::group::Pre task execution logs
[2025-02-04T01:35:26.924+0000] {taskinstance.py:2613} INFO - Dependencies all met for dep_context=non-requeueable deps ti=<TaskInstance: test_workflow.brand_mapping scheduled__2025-02-03T00:00:00+00:00 [queued]>
[2025-02-04T01:35:26.939+0000] {taskinstance.py:2613} INFO - Dependencies all met for dep_context=requeueable deps ti=<TaskInstance: test_workflow.brand_mapping scheduled__2025-02-03T00:00:00+00:00 [queued]>
[2025-02-04T01:35:26.940+0000] {taskinstance.py:2866} INFO - Starting attempt 1 of 1
[2025-02-04T01:35:26.962+0000] {taskinstance.py:2889} INFO - Executing <Task(_PythonDecoratedOperator): brand_mapping> on 2025-02-03 00:00:00+00:00
[2025-02-04T01:35:26.977+0000] {warnings.py:112} WARNING - /home/***/.local/lib/python3.12/site-packages/***/task/task_runner/standard_task_runner.py:70: DeprecationWarning: This process (pid=2274) is multi-threaded, use of fork() may lead to deadlocks in the child.
  pid = os.fork()

[2025-02-04T01:35:26.979+0000] {standard_task_runner.py:72} INFO - Started process 2279 to run task
[2025-02-04T01:35:26.981+0000] {standard_task_runner.py:104} INFO - Running: ['***', 'tasks', 'run', 'test_workflow', 'brand_mapping', 'scheduled__2025-02-03T00:00:00+00:00', '--job-id', '16', '--raw', '--subdir', 'DAGS_FOLDER/test_dag.py', '--cfg-path', '/tmp/tmp1s0yd4k1']
[2025-02-04T01:35:26.983+0000] {standard_task_runner.py:105} INFO - Job 16: Subtask brand_mapping
[2025-02-04T01:35:27.114+0000] {task_command.py:467} INFO - Running <TaskInstance: test_workflow.brand_mapping scheduled__2025-02-03T00:00:00+00:00 [running]> on host 5f60c0b9c21b
[2025-02-04T01:35:27.311+0000] {taskinstance.py:3132} INFO - Exporting env vars: AIRFLOW_CTX_DAG_OWNER='***' AIRFLOW_CTX_DAG_ID='test_workflow' AIRFLOW_CTX_TASK_ID='brand_mapping' AIRFLOW_CTX_EXECUTION_DATE='2025-02-03T00:00:00+00:00' AIRFLOW_CTX_TRY_NUMBER='1' AIRFLOW_CTX_DAG_RUN_ID='scheduled__2025-02-03T00:00:00+00:00'
[2025-02-04T01:35:27.313+0000] {logging_mixin.py:190} INFO - Task instance is in running state
[2025-02-04T01:35:27.313+0000] {logging_mixin.py:190} INFO -  Previous state of the Task instance: queued
[2025-02-04T01:35:27.313+0000] {logging_mixin.py:190} INFO - Current task name:brand_mapping state:running start_date:2025-02-04 01:35:26.925241+00:00
[2025-02-04T01:35:27.313+0000] {logging_mixin.py:190} INFO - Dag name:test_workflow and current dag run status:running
[2025-02-04T01:35:27.314+0000] {taskinstance.py:731} INFO - ::endgroup::
[2025-02-04T01:35:27.332+0000] {taskinstance.py:3311} ERROR - Task failed with exception
Traceback (most recent call last):
  File "/home/airflow/.local/lib/python3.12/site-packages/urllib3/connection.py", line 199, in _new_conn
    sock = connection.create_connection(
           ^^^^^^^^^^^^^^^^^^^^^^^^^^^^^
  File "/home/airflow/.local/lib/python3.12/site-packages/urllib3/util/connection.py", line 60, in create_connection
    for res in socket.getaddrinfo(host, port, family, socket.SOCK_STREAM):
               ^^^^^^^^^^^^^^^^^^^^^^^^^^^^^^^^^^^^^^^^^^^^^^^^^^^^^^^^^^
  File "/usr/local/lib/python3.12/socket.py", line 976, in getaddrinfo
    for res in _socket.getaddrinfo(host, port, family, type, proto, flags):
               ^^^^^^^^^^^^^^^^^^^^^^^^^^^^^^^^^^^^^^^^^^^^^^^^^^^^^^^^^^^
socket.gaierror: [Errno -3] Temporary failure in name resolution

The above exception was the direct cause of the following exception:

Traceback (most recent call last):
  File "/home/airflow/.local/lib/python3.12/site-packages/urllib3/connectionpool.py", line 789, in urlopen
    response = self._make_request(
               ^^^^^^^^^^^^^^^^^^^
  File "/home/airflow/.local/lib/python3.12/site-packages/urllib3/connectionpool.py", line 490, in _make_request
    raise new_e
  File "/home/airflow/.local/lib/python3.12/site-packages/urllib3/connectionpool.py", line 466, in _make_request
    self._validate_conn(conn)
  File "/home/airflow/.local/lib/python3.12/site-packages/urllib3/connectionpool.py", line 1095, in _validate_conn
    conn.connect()
  File "/home/airflow/.local/lib/python3.12/site-packages/urllib3/connection.py", line 693, in connect
    self.sock = sock = self._new_conn()
                       ^^^^^^^^^^^^^^^^
  File "/home/airflow/.local/lib/python3.12/site-packages/urllib3/connection.py", line 206, in _new_conn
    raise NameResolutionError(self.host, self, e) from e
urllib3.exceptions.NameResolutionError: <urllib3.connection.HTTPSConnection object at 0x7104042ea720>: Failed to resolve 'listing.cardekho.com' ([Errno -3] Temporary failure in name resolution)

The above exception was the direct cause of the following exception:

Traceback (most recent call last):
  File "/home/airflow/.local/lib/python3.12/site-packages/requests/adapters.py", line 667, in send
    resp = conn.urlopen(
           ^^^^^^^^^^^^^
  File "/home/airflow/.local/lib/python3.12/site-packages/urllib3/connectionpool.py", line 843, in urlopen
    retries = retries.increment(
              ^^^^^^^^^^^^^^^^^^
  File "/home/airflow/.local/lib/python3.12/site-packages/urllib3/util/retry.py", line 519, in increment
    raise MaxRetryError(_pool, url, reason) from reason  # type: ignore[arg-type]
    ^^^^^^^^^^^^^^^^^^^^^^^^^^^^^^^^^^^^^^^^^^^^^^^^^^^
urllib3.exceptions.MaxRetryError: HTTPSConnectionPool(host='listing.cardekho.com', port=443): Max retries exceeded with url: /api/v1/srp-listings?cityId=105&connectoid=a223ce8e-09eb-2670-52c8-170d94d8ddad&sessionid=c99f39fe3c0b18e3a027c0d3791ac0ed&lang_code=en&regionId=0&searchstring=used-cars%2Bin%2Bbangalore&pagefrom=0&sortby=created_date&sortorder=desc&mink=&maxk=&dealer_id=null&regCityNames=&regStateNames=&cellValue=&pagination=%7B%7D&carsAd=%5B%5D&device=web&userLat=&userLng= (Caused by NameResolutionError("<urllib3.connection.HTTPSConnection object at 0x7104042ea720>: Failed to resolve 'listing.cardekho.com' ([Errno -3] Temporary failure in name resolution)"))

During handling of the above exception, another exception occurred:

Traceback (most recent call last):
  File "/home/airflow/.local/lib/python3.12/site-packages/airflow/models/taskinstance.py", line 767, in _execute_task
    result = _execute_callable(context=context, **execute_callable_kwargs)
             ^^^^^^^^^^^^^^^^^^^^^^^^^^^^^^^^^^^^^^^^^^^^^^^^^^^^^^^^^^^^^
  File "/home/airflow/.local/lib/python3.12/site-packages/airflow/models/taskinstance.py", line 733, in _execute_callable
    return ExecutionCallableRunner(
           ^^^^^^^^^^^^^^^^^^^^^^^^
  File "/home/airflow/.local/lib/python3.12/site-packages/airflow/utils/operator_helpers.py", line 252, in run
    return self.func(*args, **kwargs)
           ^^^^^^^^^^^^^^^^^^^^^^^^^^
  File "/home/airflow/.local/lib/python3.12/site-packages/airflow/models/baseoperator.py", line 422, in wrapper
    return func(self, *args, **kwargs)
           ^^^^^^^^^^^^^^^^^^^^^^^^^^^
  File "/home/airflow/.local/lib/python3.12/site-packages/airflow/decorators/base.py", line 266, in execute
    return_value = super().execute(context)
                   ^^^^^^^^^^^^^^^^^^^^^^^^
  File "/home/airflow/.local/lib/python3.12/site-packages/airflow/models/baseoperator.py", line 422, in wrapper
    return func(self, *args, **kwargs)
           ^^^^^^^^^^^^^^^^^^^^^^^^^^^
  File "/home/airflow/.local/lib/python3.12/site-packages/airflow/operators/python.py", line 238, in execute
    return_value = self.execute_callable()
                   ^^^^^^^^^^^^^^^^^^^^^^^
  File "/home/airflow/.local/lib/python3.12/site-packages/airflow/operators/python.py", line 256, in execute_callable
    return runner.run(*self.op_args, **self.op_kwargs)
           ^^^^^^^^^^^^^^^^^^^^^^^^^^^^^^^^^^^^^^^^^^^
  File "/home/airflow/.local/lib/python3.12/site-packages/airflow/utils/operator_helpers.py", line 252, in run
    return self.func(*args, **kwargs)
           ^^^^^^^^^^^^^^^^^^^^^^^^^^
  File "/opt/airflow/dags/lib/extract_brand_mapping.py", line 50, in brand_mapping
    requests.request(
  File "/home/airflow/.local/lib/python3.12/site-packages/requests/api.py", line 59, in request
    return session.request(method=method, url=url, **kwargs)
           ^^^^^^^^^^^^^^^^^^^^^^^^^^^^^^^^^^^^^^^^^^^^^^^^^
  File "/home/airflow/.local/lib/python3.12/site-packages/requests/sessions.py", line 589, in request
    resp = self.send(prep, **send_kwargs)
           ^^^^^^^^^^^^^^^^^^^^^^^^^^^^^^
  File "/home/airflow/.local/lib/python3.12/site-packages/requests/sessions.py", line 703, in send
    r = adapter.send(request, **kwargs)
        ^^^^^^^^^^^^^^^^^^^^^^^^^^^^^^^
  File "/home/airflow/.local/lib/python3.12/site-packages/requests/adapters.py", line 700, in send
    raise ConnectionError(e, request=request)
requests.exceptions.ConnectionError: HTTPSConnectionPool(host='listing.cardekho.com', port=443): Max retries exceeded with url: /api/v1/srp-listings?cityId=105&connectoid=a223ce8e-09eb-2670-52c8-170d94d8ddad&sessionid=c99f39fe3c0b18e3a027c0d3791ac0ed&lang_code=en&regionId=0&searchstring=used-cars%2Bin%2Bbangalore&pagefrom=0&sortby=created_date&sortorder=desc&mink=&maxk=&dealer_id=null&regCityNames=&regStateNames=&cellValue=&pagination=%7B%7D&carsAd=%5B%5D&device=web&userLat=&userLng= (Caused by NameResolutionError("<urllib3.connection.HTTPSConnection object at 0x7104042ea720>: Failed to resolve 'listing.cardekho.com' ([Errno -3] Temporary failure in name resolution)"))
[2025-02-04T01:35:27.361+0000] {logging_mixin.py:190} INFO - Task instance in failure state
[2025-02-04T01:35:27.362+0000] {logging_mixin.py:190} INFO - Task start:2025-02-04 01:35:26.925241+00:00 end:2025-02-04 01:35:27.361000+00:00 duration:0.435759
[2025-02-04T01:35:27.363+0000] {logging_mixin.py:190} INFO - Task:<Task(_PythonDecoratedOperator): brand_mapping> dag:<DAG: test_workflow> dagrun:<DagRun test_workflow @ 2025-02-03 00:00:00+00:00: scheduled__2025-02-03T00:00:00+00:00, state:running, queued_at: 2025-02-04 01:35:23.672976+00:00. externally triggered: False>
[2025-02-04T01:35:27.364+0000] {logging_mixin.py:190} INFO - Failure caused by HTTPSConnectionPool(host='listing.cardekho.com', port=443): Max retries exceeded with url: /api/v1/srp-listings?cityId=105&connectoid=a223ce8e-09eb-2670-52c8-170d94d8ddad&sessionid=c99f39fe3c0b18e3a027c0d3791ac0ed&lang_code=en&regionId=0&searchstring=used-cars%2Bin%2Bbangalore&pagefrom=0&sortby=created_date&sortorder=desc&mink=&maxk=&dealer_id=null&regCityNames=&regStateNames=&cellValue=&pagination=%7B%7D&carsAd=%5B%5D&device=web&userLat=&userLng= (Caused by NameResolutionError("<urllib3.connection.HTTPSConnection object at 0x7104042ea720>: Failed to resolve 'listing.cardekho.com' ([Errno -3] Temporary failure in name resolution)"))
[2025-02-04T01:35:27.365+0000] {taskinstance.py:1225} INFO - Marking task as FAILED. dag_id=test_workflow, task_id=brand_mapping, run_id=scheduled__2025-02-03T00:00:00+00:00, execution_date=20250203T000000, start_date=20250204T013526, end_date=20250204T013527
[2025-02-04T01:35:27.387+0000] {taskinstance.py:340} INFO - ::group::Post task execution logs
[2025-02-04T01:35:27.388+0000] {standard_task_runner.py:124} ERROR - Failed to execute job 16 for task brand_mapping (HTTPSConnectionPool(host='listing.cardekho.com', port=443): Max retries exceeded with url: /api/v1/srp-listings?cityId=105&connectoid=a223ce8e-09eb-2670-52c8-170d94d8ddad&sessionid=c99f39fe3c0b18e3a027c0d3791ac0ed&lang_code=en&regionId=0&searchstring=used-cars%2Bin%2Bbangalore&pagefrom=0&sortby=created_date&sortorder=desc&mink=&maxk=&dealer_id=null&regCityNames=&regStateNames=&cellValue=&pagination=%7B%7D&carsAd=%5B%5D&device=web&userLat=&userLng= (Caused by NameResolutionError("<urllib3.connection.HTTPSConnection object at 0x7104042ea720>: Failed to resolve 'listing.cardekho.com' ([Errno -3] Temporary failure in name resolution)")); 2279)
Traceback (most recent call last):
  File "/home/airflow/.local/lib/python3.12/site-packages/urllib3/connection.py", line 199, in _new_conn
    sock = connection.create_connection(
           ^^^^^^^^^^^^^^^^^^^^^^^^^^^^^
  File "/home/airflow/.local/lib/python3.12/site-packages/urllib3/util/connection.py", line 60, in create_connection
    for res in socket.getaddrinfo(host, port, family, socket.SOCK_STREAM):
               ^^^^^^^^^^^^^^^^^^^^^^^^^^^^^^^^^^^^^^^^^^^^^^^^^^^^^^^^^^
  File "/usr/local/lib/python3.12/socket.py", line 976, in getaddrinfo
    for res in _socket.getaddrinfo(host, port, family, type, proto, flags):
               ^^^^^^^^^^^^^^^^^^^^^^^^^^^^^^^^^^^^^^^^^^^^^^^^^^^^^^^^^^^
socket.gaierror: [Errno -3] Temporary failure in name resolution

The above exception was the direct cause of the following exception:

Traceback (most recent call last):
  File "/home/airflow/.local/lib/python3.12/site-packages/urllib3/connectionpool.py", line 789, in urlopen
    response = self._make_request(
               ^^^^^^^^^^^^^^^^^^^
  File "/home/airflow/.local/lib/python3.12/site-packages/urllib3/connectionpool.py", line 490, in _make_request
    raise new_e
  File "/home/airflow/.local/lib/python3.12/site-packages/urllib3/connectionpool.py", line 466, in _make_request
    self._validate_conn(conn)
  File "/home/airflow/.local/lib/python3.12/site-packages/urllib3/connectionpool.py", line 1095, in _validate_conn
    conn.connect()
  File "/home/airflow/.local/lib/python3.12/site-packages/urllib3/connection.py", line 693, in connect
    self.sock = sock = self._new_conn()
                       ^^^^^^^^^^^^^^^^
  File "/home/airflow/.local/lib/python3.12/site-packages/urllib3/connection.py", line 206, in _new_conn
    raise NameResolutionError(self.host, self, e) from e
urllib3.exceptions.NameResolutionError: <urllib3.connection.HTTPSConnection object at 0x7104042ea720>: Failed to resolve 'listing.cardekho.com' ([Errno -3] Temporary failure in name resolution)

The above exception was the direct cause of the following exception:

Traceback (most recent call last):
  File "/home/airflow/.local/lib/python3.12/site-packages/requests/adapters.py", line 667, in send
    resp = conn.urlopen(
           ^^^^^^^^^^^^^
  File "/home/airflow/.local/lib/python3.12/site-packages/urllib3/connectionpool.py", line 843, in urlopen
    retries = retries.increment(
              ^^^^^^^^^^^^^^^^^^
  File "/home/airflow/.local/lib/python3.12/site-packages/urllib3/util/retry.py", line 519, in increment
    raise MaxRetryError(_pool, url, reason) from reason  # type: ignore[arg-type]
    ^^^^^^^^^^^^^^^^^^^^^^^^^^^^^^^^^^^^^^^^^^^^^^^^^^^
urllib3.exceptions.MaxRetryError: HTTPSConnectionPool(host='listing.cardekho.com', port=443): Max retries exceeded with url: /api/v1/srp-listings?cityId=105&connectoid=a223ce8e-09eb-2670-52c8-170d94d8ddad&sessionid=c99f39fe3c0b18e3a027c0d3791ac0ed&lang_code=en&regionId=0&searchstring=used-cars%2Bin%2Bbangalore&pagefrom=0&sortby=created_date&sortorder=desc&mink=&maxk=&dealer_id=null&regCityNames=&regStateNames=&cellValue=&pagination=%7B%7D&carsAd=%5B%5D&device=web&userLat=&userLng= (Caused by NameResolutionError("<urllib3.connection.HTTPSConnection object at 0x7104042ea720>: Failed to resolve 'listing.cardekho.com' ([Errno -3] Temporary failure in name resolution)"))

During handling of the above exception, another exception occurred:

Traceback (most recent call last):
  File "/home/airflow/.local/lib/python3.12/site-packages/airflow/task/task_runner/standard_task_runner.py", line 117, in _start_by_fork
    ret = args.func(args, dag=self.dag)
          ^^^^^^^^^^^^^^^^^^^^^^^^^^^^^
  File "/home/airflow/.local/lib/python3.12/site-packages/airflow/cli/cli_config.py", line 49, in command
    return func(*args, **kwargs)
           ^^^^^^^^^^^^^^^^^^^^^
  File "/home/airflow/.local/lib/python3.12/site-packages/airflow/utils/cli.py", line 116, in wrapper
    return f(*args, **kwargs)
           ^^^^^^^^^^^^^^^^^^
  File "/home/airflow/.local/lib/python3.12/site-packages/airflow/cli/commands/task_command.py", line 483, in task_run
    task_return_code = _run_task_by_selected_method(args, _dag, ti)
                       ^^^^^^^^^^^^^^^^^^^^^^^^^^^^^^^^^^^^^^^^^^^^
  File "/home/airflow/.local/lib/python3.12/site-packages/airflow/cli/commands/task_command.py", line 256, in _run_task_by_selected_method
    return _run_raw_task(args, ti)
           ^^^^^^^^^^^^^^^^^^^^^^^
  File "/home/airflow/.local/lib/python3.12/site-packages/airflow/cli/commands/task_command.py", line 341, in _run_raw_task
    return ti._run_raw_task(
           ^^^^^^^^^^^^^^^^^
  File "/home/airflow/.local/lib/python3.12/site-packages/airflow/utils/session.py", line 97, in wrapper
    return func(*args, session=session, **kwargs)
           ^^^^^^^^^^^^^^^^^^^^^^^^^^^^^^^^^^^^^^
  File "/home/airflow/.local/lib/python3.12/site-packages/airflow/models/taskinstance.py", line 3005, in _run_raw_task
    return _run_raw_task(
           ^^^^^^^^^^^^^^
  File "/home/airflow/.local/lib/python3.12/site-packages/airflow/models/taskinstance.py", line 273, in _run_raw_task
    TaskInstance._execute_task_with_callbacks(
  File "/home/airflow/.local/lib/python3.12/site-packages/airflow/models/taskinstance.py", line 3159, in _execute_task_with_callbacks
    result = self._execute_task(context, task_orig)
             ^^^^^^^^^^^^^^^^^^^^^^^^^^^^^^^^^^^^^^
  File "/home/airflow/.local/lib/python3.12/site-packages/airflow/models/taskinstance.py", line 3183, in _execute_task
    return _execute_task(self, context, task_orig)
           ^^^^^^^^^^^^^^^^^^^^^^^^^^^^^^^^^^^^^^^
  File "/home/airflow/.local/lib/python3.12/site-packages/airflow/models/taskinstance.py", line 767, in _execute_task
    result = _execute_callable(context=context, **execute_callable_kwargs)
             ^^^^^^^^^^^^^^^^^^^^^^^^^^^^^^^^^^^^^^^^^^^^^^^^^^^^^^^^^^^^^
  File "/home/airflow/.local/lib/python3.12/site-packages/airflow/models/taskinstance.py", line 733, in _execute_callable
    return ExecutionCallableRunner(
           ^^^^^^^^^^^^^^^^^^^^^^^^
  File "/home/airflow/.local/lib/python3.12/site-packages/airflow/utils/operator_helpers.py", line 252, in run
    return self.func(*args, **kwargs)
           ^^^^^^^^^^^^^^^^^^^^^^^^^^
  File "/home/airflow/.local/lib/python3.12/site-packages/airflow/models/baseoperator.py", line 422, in wrapper
    return func(self, *args, **kwargs)
           ^^^^^^^^^^^^^^^^^^^^^^^^^^^
  File "/home/airflow/.local/lib/python3.12/site-packages/airflow/decorators/base.py", line 266, in execute
    return_value = super().execute(context)
                   ^^^^^^^^^^^^^^^^^^^^^^^^
  File "/home/airflow/.local/lib/python3.12/site-packages/airflow/models/baseoperator.py", line 422, in wrapper
    return func(self, *args, **kwargs)
           ^^^^^^^^^^^^^^^^^^^^^^^^^^^
  File "/home/airflow/.local/lib/python3.12/site-packages/airflow/operators/python.py", line 238, in execute
    return_value = self.execute_callable()
                   ^^^^^^^^^^^^^^^^^^^^^^^
  File "/home/airflow/.local/lib/python3.12/site-packages/airflow/operators/python.py", line 256, in execute_callable
    return runner.run(*self.op_args, **self.op_kwargs)
           ^^^^^^^^^^^^^^^^^^^^^^^^^^^^^^^^^^^^^^^^^^^
  File "/home/airflow/.local/lib/python3.12/site-packages/airflow/utils/operator_helpers.py", line 252, in run
    return self.func(*args, **kwargs)
           ^^^^^^^^^^^^^^^^^^^^^^^^^^
  File "/opt/airflow/dags/lib/extract_brand_mapping.py", line 50, in brand_mapping
    requests.request(
  File "/home/airflow/.local/lib/python3.12/site-packages/requests/api.py", line 59, in request
    return session.request(method=method, url=url, **kwargs)
           ^^^^^^^^^^^^^^^^^^^^^^^^^^^^^^^^^^^^^^^^^^^^^^^^^
  File "/home/airflow/.local/lib/python3.12/site-packages/requests/sessions.py", line 589, in request
    resp = self.send(prep, **send_kwargs)
           ^^^^^^^^^^^^^^^^^^^^^^^^^^^^^^
  File "/home/airflow/.local/lib/python3.12/site-packages/requests/sessions.py", line 703, in send
    r = adapter.send(request, **kwargs)
        ^^^^^^^^^^^^^^^^^^^^^^^^^^^^^^^
  File "/home/airflow/.local/lib/python3.12/site-packages/requests/adapters.py", line 700, in send
    raise ConnectionError(e, request=request)
requests.exceptions.ConnectionError: HTTPSConnectionPool(host='listing.cardekho.com', port=443): Max retries exceeded with url: /api/v1/srp-listings?cityId=105&connectoid=a223ce8e-09eb-2670-52c8-170d94d8ddad&sessionid=c99f39fe3c0b18e3a027c0d3791ac0ed&lang_code=en&regionId=0&searchstring=used-cars%2Bin%2Bbangalore&pagefrom=0&sortby=created_date&sortorder=desc&mink=&maxk=&dealer_id=null&regCityNames=&regStateNames=&cellValue=&pagination=%7B%7D&carsAd=%5B%5D&device=web&userLat=&userLng= (Caused by NameResolutionError("<urllib3.connection.HTTPSConnection object at 0x7104042ea720>: Failed to resolve 'listing.cardekho.com' ([Errno -3] Temporary failure in name resolution)"))
[2025-02-04T01:35:27.438+0000] {local_task_job_runner.py:266} INFO - Task exited with return code 1
[2025-02-04T01:35:27.470+0000] {taskinstance.py:3895} INFO - 0 downstream tasks scheduled from follow-on schedule check
[2025-02-04T01:35:27.472+0000] {local_task_job_runner.py:245} INFO - ::endgroup::
[2025-02-04T09:16:29.330+0000] {local_task_job_runner.py:123} INFO - ::group::Pre task execution logs
[2025-02-04T09:16:29.346+0000] {taskinstance.py:2613} INFO - Dependencies all met for dep_context=non-requeueable deps ti=<TaskInstance: test_workflow.brand_mapping scheduled__2025-02-03T00:00:00+00:00 [queued]>
[2025-02-04T09:16:29.352+0000] {taskinstance.py:2613} INFO - Dependencies all met for dep_context=requeueable deps ti=<TaskInstance: test_workflow.brand_mapping scheduled__2025-02-03T00:00:00+00:00 [queued]>
[2025-02-04T09:16:29.353+0000] {taskinstance.py:2866} INFO - Starting attempt 1 of 1
[2025-02-04T09:16:29.366+0000] {taskinstance.py:2889} INFO - Executing <Task(_PythonDecoratedOperator): brand_mapping> on 2025-02-03 00:00:00+00:00
[2025-02-04T09:16:29.374+0000] {warnings.py:112} WARNING - /home/***/.local/lib/python3.12/site-packages/***/task/task_runner/standard_task_runner.py:70: DeprecationWarning: This process (pid=131) is multi-threaded, use of fork() may lead to deadlocks in the child.
  pid = os.fork()

[2025-02-04T09:16:29.375+0000] {standard_task_runner.py:72} INFO - Started process 141 to run task
[2025-02-04T09:16:29.376+0000] {standard_task_runner.py:104} INFO - Running: ['***', 'tasks', 'run', 'test_workflow', 'brand_mapping', 'scheduled__2025-02-03T00:00:00+00:00', '--job-id', '4', '--raw', '--subdir', 'DAGS_FOLDER/test_dag.py', '--cfg-path', '/tmp/tmp190ov071']
[2025-02-04T09:16:29.377+0000] {standard_task_runner.py:105} INFO - Job 4: Subtask brand_mapping
[2025-02-04T09:16:29.416+0000] {task_command.py:467} INFO - Running <TaskInstance: test_workflow.brand_mapping scheduled__2025-02-03T00:00:00+00:00 [running]> on host 8e470e23ca34
[2025-02-04T09:16:29.491+0000] {taskinstance.py:3132} INFO - Exporting env vars: AIRFLOW_CTX_DAG_OWNER='***' AIRFLOW_CTX_DAG_ID='test_workflow' AIRFLOW_CTX_TASK_ID='brand_mapping' AIRFLOW_CTX_EXECUTION_DATE='2025-02-03T00:00:00+00:00' AIRFLOW_CTX_TRY_NUMBER='1' AIRFLOW_CTX_DAG_RUN_ID='scheduled__2025-02-03T00:00:00+00:00'
[2025-02-04T09:16:29.492+0000] {logging_mixin.py:190} INFO - Task instance is in running state
[2025-02-04T09:16:29.493+0000] {logging_mixin.py:190} INFO -  Previous state of the Task instance: queued
[2025-02-04T09:16:29.493+0000] {logging_mixin.py:190} INFO - Current task name:brand_mapping state:running start_date:2025-02-04 09:16:29.346427+00:00
[2025-02-04T09:16:29.493+0000] {logging_mixin.py:190} INFO - Dag name:test_workflow and current dag run status:running
[2025-02-04T09:16:29.493+0000] {taskinstance.py:731} INFO - ::endgroup::
[2025-02-04T09:16:29.888+0000] {python.py:240} INFO - Done. Returned value was: [(['volvo'], 11), (['jaguar'], 8), (['porsche'], 6), (['renault'], 249)]
[2025-02-04T09:16:29.920+0000] {taskinstance.py:340} INFO - ::group::Post task execution logs
[2025-02-04T09:16:29.921+0000] {taskinstance.py:352} INFO - Marking task as SUCCESS. dag_id=test_workflow, task_id=brand_mapping, run_id=scheduled__2025-02-03T00:00:00+00:00, execution_date=20250203T000000, start_date=20250204T091629, end_date=20250204T091629
[2025-02-04T09:16:29.940+0000] {logging_mixin.py:190} INFO - Task instance in success state
[2025-02-04T09:16:29.941+0000] {logging_mixin.py:190} INFO -  Previous state of the Task instance: running
[2025-02-04T09:16:29.941+0000] {logging_mixin.py:190} INFO - Dag name:test_workflow queued_at:2025-02-04 09:16:26.187049+00:00
[2025-02-04T09:16:29.942+0000] {logging_mixin.py:190} INFO - Task hostname:8e470e23ca34 operator:_PythonDecoratedOperator
[2025-02-04T09:16:29.990+0000] {local_task_job_runner.py:266} INFO - Task exited with return code 0
[2025-02-04T09:16:30.062+0000] {taskinstance.py:3895} INFO - 0 downstream tasks scheduled from follow-on schedule check
[2025-02-04T09:16:30.063+0000] {local_task_job_runner.py:245} INFO - ::endgroup::
